<?xml version='1.0'?>
<sdf version='1.6'>
		<model name="FourBarPlanarLinkage">
			<self_collide>true</self_collide>
			<pose>0.0 0.0 0.0 0.0 0.0 0.0</pose>
			<!-- Start of parts of the pmodel FourBarPlanarLinkage -->
			<!-- End of parts of the pmodel FourBarPlanarLinkage -->
			
			<!-- Start of links of the pmodel FourBarPlanarLinkage -->
			<!-- link full name is FourBarPlanarLinkage::Link1 -->
			<link name="1-Link1">
					<pose>0.0 0.0 2.0 0.0 0.0 0.0</pose>
					<inertial>
						<pose>0.0 0.0 0.0 0.0 0.0 0.0</pose>
						<inertia>
							<ixx>1.0</ixx>
							<ixy>0.0</ixy>
							<ixz>0.0</ixz>
							<iyy>1.0</iyy>
							<iyz>0.0</iyz>
							<izz>1.0</izz>
						</inertia>
						<mass>1.0</mass>
					</inertial>
					<!-- body full name is FourBarPlanarLinkage::Link1::Link1 -->
					<collision name="1--Link1">
						<laser_retro>0.0</laser_retro>
						<pose>0.0 0.0 0.0 0.0 0.0 0.0</pose>
						<geometry>
							<cylinder>
								<radius>0.25</radius>
								<length>4</length>
							</cylinder>
						</geometry>
						<surface>
							<bounce>
								<restitution_coefficient>0.0</restitution_coefficient>
								<threshold>100000.0</threshold>
							</bounce>
							<friction>
								<ode>
									<mu>1.0</mu>
									<mu2>1.0</mu2>
									<fdir1>0.0 0.0 0.0</fdir1>
									<slip1>0.0</slip1>
									<slip2>0.0</slip2>
								</ode>
								<torsional>
									<coefficient>1.0</coefficient>
									<surface_radius>0.0</surface_radius>
								</torsional>
							</friction>
						</surface>
					</collision>
					<visual name="1--Link1">
						<laser_retro>0.0</laser_retro>
						<pose>0.0 0.0 0.0 0.0 0.0 0.0</pose>
						<geometry>
							<cylinder>
								<radius>0.25</radius>
								<length>4</length>
							</cylinder>
						</geometry>
					</visual>
			</link>	
			<!-- link full name is FourBarPlanarLinkage::Link2 -->
			<link name="2-Link2">
					<pose>0.0 2.0 4.0 1.5700000524520874 0.0 0.0</pose>
					<inertial>
						<pose>0.0 0.0 0.0 0.0 0.0 0.0</pose>
						<inertia>
							<ixx>1.0</ixx>
							<ixy>0.0</ixy>
							<ixz>0.0</ixz>
							<iyy>1.0</iyy>
							<iyz>0.0</iyz>
							<izz>1.0</izz>
						</inertia>
						<mass>1.0</mass>
					</inertial>
					<!-- body full name is FourBarPlanarLinkage::Link2::Link2 -->
					<collision name="2--Link2">
						<laser_retro>0.0</laser_retro>
						<pose>0.0 0.0 0.0 0.0 0.0 0.0</pose>
						<geometry>
							<cylinder>
								<radius>0.25</radius>
								<length>4</length>
							</cylinder>
						</geometry>
						<surface>
							<bounce>
								<restitution_coefficient>0.0</restitution_coefficient>
								<threshold>100000.0</threshold>
							</bounce>
							<friction>
								<ode>
									<mu>1.0</mu>
									<mu2>1.0</mu2>
									<fdir1>0.0 0.0 0.0</fdir1>
									<slip1>0.0</slip1>
									<slip2>0.0</slip2>
								</ode>
								<torsional>
									<coefficient>1.0</coefficient>
									<surface_radius>0.0</surface_radius>
								</torsional>
							</friction>
						</surface>
					</collision>
					<visual name="2--Link2">
						<laser_retro>0.0</laser_retro>
						<pose>0.0 0.0 0.0 0.0 0.0 0.0</pose>
						<geometry>
							<cylinder>
								<radius>0.25</radius>
								<length>4</length>
							</cylinder>
						</geometry>
					</visual>
			</link>	
			<!-- link full name is FourBarPlanarLinkage::Link3 -->
			<link name="3-Link3">
					<pose>0.0 4.0 2.0 0.0 0.0 0.0</pose>
					<inertial>
						<pose>0.0 0.0 0.0 0.0 0.0 0.0</pose>
						<inertia>
							<ixx>1.0</ixx>
							<ixy>0.0</ixy>
							<ixz>0.0</ixz>
							<iyy>1.0</iyy>
							<iyz>0.0</iyz>
							<izz>1.0</izz>
						</inertia>
						<mass>1.0</mass>
					</inertial>
					<!-- body full name is FourBarPlanarLinkage::Link3::Link3 -->
					<collision name="3--Link3">
						<laser_retro>0.0</laser_retro>
						<pose>0.0 0.0 0.0 0.0 0.0 0.0</pose>
						<geometry>
							<cylinder>
								<radius>0.25</radius>
								<length>4</length>
							</cylinder>
						</geometry>
						<surface>
							<bounce>
								<restitution_coefficient>0.0</restitution_coefficient>
								<threshold>100000.0</threshold>
							</bounce>
							<friction>
								<ode>
									<mu>1.0</mu>
									<mu2>1.0</mu2>
									<fdir1>0.0 0.0 0.0</fdir1>
									<slip1>0.0</slip1>
									<slip2>0.0</slip2>
								</ode>
								<torsional>
									<coefficient>1.0</coefficient>
									<surface_radius>0.0</surface_radius>
								</torsional>
							</friction>
						</surface>
					</collision>
					<visual name="3--Link3">
						<laser_retro>0.0</laser_retro>
						<pose>0.0 0.0 0.0 0.0 0.0 0.0</pose>
						<geometry>
							<cylinder>
								<radius>0.25</radius>
								<length>4</length>
							</cylinder>
						</geometry>
					</visual>
			</link>	
			<!-- link full name is FourBarPlanarLinkage::Link4 -->
			<link name="4-Link4">
					<pose>0.0 2.0 0.0 1.5700000524520874 0.0 0.0</pose>
					<inertial>
						<pose>0.0 0.0 0.0 0.0 0.0 0.0</pose>
						<inertia>
							<ixx>1.0</ixx>
							<ixy>0.0</ixy>
							<ixz>0.0</ixz>
							<iyy>1.0</iyy>
							<iyz>0.0</iyz>
							<izz>1.0</izz>
						</inertia>
						<mass>1.0</mass>
					</inertial>
					<!-- body full name is FourBarPlanarLinkage::Link4::Link4 -->
					<collision name="4--Link4">
						<laser_retro>0.0</laser_retro>
						<pose>0.0 0.0 0.0 0.0 0.0 0.0</pose>
						<geometry>
							<cylinder>
								<radius>0.23999999463558197</radius>
								<length>4</length>
							</cylinder>
						</geometry>
						<surface>
							<bounce>
								<restitution_coefficient>0.0</restitution_coefficient>
								<threshold>100000.0</threshold>
							</bounce>
							<friction>
								<ode>
									<mu>1.0</mu>
									<mu2>1.0</mu2>
									<fdir1>0.0 0.0 0.0</fdir1>
									<slip1>0.0</slip1>
									<slip2>0.0</slip2>
								</ode>
								<torsional>
									<coefficient>1.0</coefficient>
									<surface_radius>0.0</surface_radius>
								</torsional>
							</friction>
						</surface>
					</collision>
					<visual name="4--Link4">
						<laser_retro>0.0</laser_retro>
						<pose>0.0 0.0 0.0 0.0 0.0 0.0</pose>
						<geometry>
							<cylinder>
								<radius>0.23999999463558197</radius>
								<length>4</length>
							</cylinder>
						</geometry>
					</visual>
			</link>	
			<!-- End of links of the pmodel FourBarPlanarLinkage -->
			
			<!-- Start of joints of the pmodel FourBarPlanarLinkage -->
			<!-- Full name of joint: FourBarPlanarLinkage::Link1::Link1Joint from FourBarPlanarLinkage::Link1 to FourBarPlanarLinkage::Link2-->
			<joint name="5-Link1Joint" type="revolute">
				<pose>0.0 -2.0015919144645298 1.9984068174298792 -1.5700000524520874 -0.0 0.0</pose>
				<parent>1-Link1</parent>
				<child>2-Link2</child>
				<!-- WARNING: The SDF generator relies on annotations of the joint 5-Link1Joint to specify in SDF aspects of the joint that are
					 accounted for in the equations. -->
				<axis>
					<xyz>1 0 0</xyz>
					<dynamics>
						<damping>0</damping>
						<friction>0</friction>
						<spring_reference>0</spring_reference>
						<spring_stiffness>0</spring_stiffness>
					</dynamics>
					<limit>
						<lower>-1.5707963705062866</lower>
						<upper>1.5707963705062866</upper>
						<velocity>5</velocity>
					</limit>
				</axis>
			</joint>
			<!-- Full name of joint: FourBarPlanarLinkage::Link2::Link2Joint from FourBarPlanarLinkage::Link2 to FourBarPlanarLinkage::Link3-->
			<joint name="6-Link2Joint" type="revolute">
				<pose>0.0 -3.9999993659472044 2.0015925485173254 1.5700000524520874 -0.0 0.0</pose>
				<parent>2-Link2</parent>
				<child>3-Link3</child>
				<!-- WARNING: The SDF generator relies on annotations of the joint 6-Link2Joint to specify in SDF aspects of the joint that are
					 accounted for in the equations. -->
				<axis>
					<xyz>0 0 1</xyz>
					<dynamics>
						<damping>0</damping>
						<friction>0</friction>
						<spring_reference>0</spring_reference>
						<spring_stiffness>0</spring_stiffness>
					</dynamics>
					<limit>
						<lower>-6.2831854820251465</lower>
						<upper>6.2831854820251465</upper>
						<velocity>5</velocity>
					</limit>
				</axis>
			</joint>
			<!-- Full name of joint: FourBarPlanarLinkage::Link4::Link4Joint from FourBarPlanarLinkage::Link4 to FourBarPlanarLinkage::Link1-->
			<joint name="7-Link4Joint" type="revolute">
				<pose>0.0 2.0 -2.0 1.5700000524520874 -0.0 0.0</pose>
				<parent>4-Link4</parent>
				<child>1-Link1</child>
				<!-- WARNING: The SDF generator relies on annotations of the joint 7-Link4Joint to specify in SDF aspects of the joint that are
					 accounted for in the equations. -->
				<axis>
					<xyz>1 0 0</xyz>
					<dynamics>
						<damping>0</damping>
						<friction>0</friction>
						<spring_reference>0</spring_reference>
						<spring_stiffness>0</spring_stiffness>
					</dynamics>
					<limit>
						<lower>-1.5707963705062866</lower>
						<upper>1.5707963705062866</upper>
						<velocity>5</velocity>
					</limit>
				</axis>
			</joint>
			<!-- Full name of joint: FourBarPlanarLinkage::Link3::Link3Joint from FourBarPlanarLinkage::Link3 to FourBarPlanarLinkage::Link4-->
			<joint name="8-Link3Joint" type="revolute">
				<pose>0.0 2.0015919144645298 -1.9984068174298795 -1.5700000524520874 -0.0 0.0</pose>
				<parent>3-Link3</parent>
				<child>4-Link4</child>
				<!-- WARNING: The SDF generator relies on annotations of the joint 8-Link3Joint to specify in SDF aspects of the joint that are
					 accounted for in the equations. -->
				<axis>
					<xyz>1 0 0</xyz>
					<dynamics>
						<damping>0</damping>
						<friction>0</friction>
						<spring_reference>0</spring_reference>
						<spring_stiffness>0</spring_stiffness>
					</dynamics>
					<limit>
						<lower>-1.5707963705062866</lower>
						<upper>1.5707963705062866</upper>
						<velocity>5</velocity>
					</limit>
				</axis>
			</joint>
			<!-- End of joints of the pmodel FourBarPlanarLinkage -->
			
			<!-- Start of fixed connections of the pmodel FourBarPlanarLinkage -->
			<!-- End of fixed connections of the pmodel FourBarPlanarLinkage -->
		</model>
</sdf>
